Workbook

Sheet AAPL Monthly
A1: Column1 | B1: Column2 | C1: Column3 | D1: Column4 | E1: Column5 | F1: Column6 | G1: Column7 | H1: Column8 | N1: Column1
A2: Date | B2: Open | C2: High | D2: Low | E2: Close | F2: Volume | G2: Adj Close | H2: Month Date | I2: Return Close | J2: Return Adj. Close
A3: 8/3/15 | B3: 121.5 | C3: 122.57 | D3: 92 | E3: 112.760002 | F3: 79152700 | G3: 110.997612 | N3: Mean | O3: 0.0042765175
A4: 9/1/15 | B4: 110.150002 | C4: 116.889999 | D4: 107.360001 | E4: 110.300003 | F4: 60620000 | G4: 108.576057 | H4: 2015/08 | I4: =(E4-E3)/E3 -> -0.021816238 | J4: =(G4-G3)/G3 -> -0.02181628 | N4: Standard Error | O4: 0.036637873
A5: 10/1/15 | B5: 109.07 | C5: 121.220001 | D5: 107.309998 | E5: 119.5 | F5: 52797300 | G5: 117.632263 | H5: 2015/09 | I5: =(E5-E4)/E4 -> 0.083408855 | J5: =(G5-G4)/G4 -> 0.083408868 | N5: Median | O5: -0.0012875671
A6: 11/2/15 | B6: 120.800003 | C6: 123.82 | D6: 111 | E6: 118.300003 | F6: 39491000 | G6: 116.949501 | H6: 2015/10 | I6: =(E6-E5)/E5 -> -0.010041816 | J6: =(G6-G5)/G5 -> -0.005804207 | N6: Mode | O6: #N/A
A7: 12/1/15 | B7: 118.75 | C7: 119.860001 | D7: 104.82 | E7: 105.260002 | F7: 43750400 | G7: 104.058365 | H7: 2015/11 | I7: =(E7-E6)/E6 -> -0.11022824 | J7: =(G7-G6)/G6 -> -0.11022823 | N7: Standard Deviation | O7: 0.0969347
A8: 1/4/16 | B8: 102.610001 | C8: 105.849998 | D8: 92.389999 | E8: 97.339996 | F8: 70329700 | G8: 96.228775 | H8: 2015/12 | I8: =(E8-E7)/E7 -> -0.075242313 | J8: =(G8-G7)/G7 -> -0.075242293 | N8: Sample Variance | O8: 0.0093963361
A9: 2/1/16 | B9: 96.470001 | C9: 98.889999 | D9: 92.589996 | E9: 96.690002 | F9: 42303900 | G9: 96.104874 | H9: 2016/01 | I9: =(E9-E8)/E8 -> -0.0066775635 | J9: =(G9-G8)/G8 -> -0.0012875671 | N9: Kurtosis | O9: -1.2746574 | Q9: Sharpe Ratio
A10: 3/1/16 | B10: 97.650002 | C10: 110.419998 | D10: 97.419998 | E10: 108.989998 | F10: 35088000 | G10: 108.330437 | H10: 2016/02 | I10: =(E10-E9)/E9 -> 0.12721063 | J10: =(G10-G9)/G9 -> 0.12721064 | N10: Skewness | O10: -0.20698614 | Q10: =(O3-0)/O7 -> 0.044117509
A11: 4/1/16 | B11: 108.779999 | C11: 112.389999 | D11: 92.510002 | E11: 93.739998 | F11: 44805400 | G11: 93.172722 | H11: 2016/03 | I11: =(E11-E10)/E10 -> -0.1399211 | J11: =(G11-G10)/G10 -> -0.13992111 | N11: Range | O11: 0.26713175
A12: 5/2/16 | B12: 93.970001 | C12: 100.730003 | D12: 89.470001 | E12: 99.860001 | F12: 44903700 | G12: 99.860001 | H12: 2016/04 | I12: =(E12-E11)/E11 -> 0.065286997 | J12: =(G12-G11)/G11 -> 0.071772927 | N12: Minimum | O12: -0.13992111
A13: 6/1/16 | B13: 99.019997 | C13: 101.889999 | D13: 91.5 | E13: 95.599998 | F13: 37060600 | G13: 95.599998 | H13: 2016/05 | I13: =(E13-E12)/E12 -> -0.042659753 | J13: =(G13-G12)/G12 -> -0.042659753 | N13: Maximum | O13: 0.12721064
A14: 7/1/16 | B14: 95.489998 | C14: 104.550003 | D14: 94.370003 | E14: 104.209999 | F14: 34748300 | G14: 104.209999 | H14: 2016/06 | I14: =(E14-E13)/E13 -> 0.090062774 | J14: =(G14-G13)/G13 -> 0.090062774 | N14: Sum | O14: 0.029935623
A15: 8/1/16 | B15: 104.410004 | C15: 106.150002 | D15: 104.410004 | E15: 106.050003 | F15: 74998000 | G15: 106.050003 | H15: 2016/07 | I15: =(E15-E14)/E14 -> 0.017656693 | J15: =(G15-G14)/G14 -> 0.017656693 | N15: Count | O15: 7
N16: Confidence Level(95.0%) | O16: 0.089649645
E18: Converting into decimal return
A19: Date | B19: VBTLX | C19: VFIAX | E19: Date | F19: VBTLX | G19: VFIAX
A20: 40909 | B20: 0.88 | C20: 4.47 | E20: 40909 | F20: 0.0088 | G20: 0.0447
A21: Feb-12 | B21: -0.04 | C21: 4.32 | E21: Feb-12 | F21: -0.0004 | G21: 0.0432
A22: 40969 | B22: -0.57 | C22: 3.29 | E22: 40969 | F22: -0.0057 | G22: 0.0329
A23: Apr-12 | B23: 1.15 | C23: -0.63 | E23: Apr-12 | F23: 0.0115 | G23: -0.0063
A24: May-12 | B24: 0.96 | C24: -6.01 | E24: May-12 | F24: 0.0096 | G24: -0.0601
A25: 41061 | B25: 0.04 | C25: 4.12 | E25: 41061 | F25: 0.0004 | G25: 0.0412
A26: 41091 | B26: 1.39 | C26: 1.38 | E26: 41091 | F26: 0.0139 | G26: 0.0138
A27: Aug-12 | B27: 0.04 | C27: 2.25 | E27: Aug-12 | F27: 0.0004 | G27: 0.0225
A28: Sep-12 | B28: 0.12 | C28: 2.58 | E28: Sep-12 | F28: 0.0012 | G28: 0.0258
A29: Oct-12 | B29: 0.12 | C29: -1.85 | E29: Oct-12 | F29: 0.0012 | G29: -0.0185
A30: 41214 | B30: 0.2 | C30: 0.58 | E30: 41214 | F30: 0.002 | G30: 0.0058
A31: Dec-12 | B31: -0.19 | C31: 0.91 | E31: Dec-12 | F31: -0.0019 | G31: 0.0091
A32: 41275 | B32: -0.7 | C32: 5.18 | E32: 41275 | F32: -0.007 | G32: 0.0518
A33: Feb-13 | B33: 0.55 | C33: 1.35 | E33: Feb-13 | F33: 0.0055 | G33: 0.0135
A34: 41334 | B34: 0.09 | C34: 3.75 | E34: 41334 | F34: 0.0009 | G34: 0.0375
A35: Apr-13 | B35: 0.92 | C35: 1.92 | E35: Apr-13 | F35: 0.0092 | G35: 0.0192
A36: May-13 | B36: -1.7 | C36: 2.33 | E36: May-13 | F36: -0.017 | G36: 0.0233
A37: 41426 | B37: -1.64 | C37: -1.35 | E37: 41426 | F37: -0.0164 | G37: -0.0135
A38: 41456 | B38: 0.21 | C38: 5.09 | E38: 41456 | F38: 0.0021 | G38: 0.0509
A39: Aug-13 | B39: -0.63 | C39: -2.9 | E39: Aug-13 | F39: -0.0063 | G39: -0.029
A40: Sep-13 | B40: 0.97 | C40: 3.13 | E40: Sep-13 | F40: 0.0097 | G40: 0.0313
A41: Oct-13 | B41: 0.79 | C41: 4.59 | E41: Oct-13 | F41: 0.0079 | G41: 0.0459
...

Sheet MSFT_WFC_Port
G1: WFC | H1: MSFT | I1: Portfolio Return | J1: Port. Variance | K1: Port. Std. Deviation | L1: Sharpe Ratio
G2: 0 | H2: 1 | I2: =(G2*$B$5)+(H2*$E$5) -> 0.00074693549 | J2: =G2^2*$B$7^2+H2^2*$E$7^2+2*G2*H2*$C$7*$B$7*$E$7 -> 0.00021957065 | K2: =SQRT(G2^2*$B$7^2+H2^2*$E$7^2+2*G2*H2*$C$7*$B$7*$E$7) -> 0.014817916 | L2: =(I2-0)/K2 -> 0.050407592
A3: WFC | B3: (A) | D3: MSFT | E3: (B) | G3: 0.05 | H3: 0.95 | I3: =(G3*$B$5)+(H3*$E$5) -> 0.00074086609 | J3: =G3^2*$B$7^2+H3^2*$E$7^2+2*G3*H3*$C$7*$B$7*$E$7 -> 0.0002095946 | K3: =SQRT(G3^2*$B$7^2+H3^2*$E$7^2+2*G3*H3*$C$7*$B$7*$E$7) -> 0.014477382 | L3: =(I3-0)/K3 -> 0.051174037 | Q3: Tangent Portfolio Plot
C4: Expected Product of RA and RB: | G4: 0.1 | H4: 0.9 | I4: =(G4*$B$5)+(H4*$E$5) -> 0.0007347967 | J4: =G4^2*$B$7^2+H4^2*$E$7^2+2*G4*H4*$C$7*$B$7*$E$7 -> 0.00020080143 | K4: =SQRT(G4^2*$B$7^2+H4^2*$E$7^2+2*G4*H4*$C$7*$B$7*$E$7) -> 0.014170442 | L4: =(I4-0)/K4 -> 0.051854182
A5: Expected R: | B5: =WFC!O8 -> 0.00062554756 | C5: =AVERAGE(C12:C1522) -> 0.00011436301 | D5: Expected R: | E5: =MSFT!O8 -> 0.00074693549 | G5: 0.15 | H5: 0.85 | I5: =(G5*$B$5)+(H5*$E$5) -> 0.0007287273 | J5: =G5^2*$B$7^2+H5^2*$E$7^2+2*G5*H5*$C$7*$B$7*$E$7 -> 0.00019319115 | K5: =SQRT(G5^2*$B$7^2+H5^2*$E$7^2+2*G5*H5*$C$7*$B$7*$E$7) -> 0.013899322 | L5: =(I5-0)/K5 -> 0.052428981 | P5: Risk-Free Rate: | Q5: 0
A6: Variance R: | B6: =WFC!O13 -> 0.00024479745 | C6: Correlation between RA and RB: | D6: Variance R: | E6: =MSFT!O13 -> 0.00021957065 | G6: 0.2 | H6: 0.8 | I6: =(G6*$B$5)+(H6*$E$5) -> 0.0007226579 | J6: =G6^2*$B$7^2+H6^2*$E$7^2+2*G6*H6*$C$7*$B$7*$E$7 -> 0.00018676376 | K6: =SQRT(G6^2*$B$7^2+H6^2*$E$7^2+2*G6*H6*$C$7*$B$7*$E$7) -> 0.013666154 | L6: =(I6-0)/K6 -> 0.052879392
A7: Std. Dev. R. | B7: =WFC!O12 -> 0.015646004 | C7: =(C5-B5*E5)/(B7*E7) -> 0.49126632 | D7: Std. Dev. R. | E7: =MSFT!O12 -> 0.014817916 | G7: 0.25 | H7: 0.75 | I7: =(G7*$B$5)+(H7*$E$5) -> 0.00071658851 | J7: =G7^2*$B$7^2+H7^2*$E$7^2+2*G7*H7*$C$7*$B$7*$E$7 -> 0.00018151924 | K7: =SQRT(G7^2*$B$7^2+H7^2*$E$7^2+2*G7*H7*$C$7*$B$7*$E$7) -> 0.013472908 | L7: =(I7-0)/K7 -> 0.053187369 | P7: Expected Returns: | Q7: =Q9*Q8 -> 0.00070821168 | R7: =Q9*R8 -> 0.00079052922
G8: 0.3 | H8: 0.7 | I8: =(G8*$B$5)+(H8*$E$5) -> 0.00071051911 | J8: =G8^2*$B$7^2+H8^2*$E$7^2+2*G8*H8*$C$7*$B$7*$E$7 -> 0.00017745761 | K8: =SQRT(G8^2*$B$7^2+H8^2*$E$7^2+2*G8*H8*$C$7*$B$7*$E$7) -> 0.013321322 | L8: =(I8-0)/K8 -> 0.053336984 | P8: Standard deviations: | Q8: 0.013274932 | R8: 0.014817916
G9: 0.35 | H9: 0.65 | I9: =(G9*$B$5)+(H9*$E$5) -> 0.00070444971 | J9: =G9^2*$B$7^2+H9^2*$E$7^2+2*G9*H9*$C$7*$B$7*$E$7 -> 0.00017457886 | K9: =SQRT(G9^2*$B$7^2+H9^2*$E$7^2+2*G9*H9*$C$7*$B$7*$E$7) -> 0.013212829 | L9: =(I9-0)/K9 -> 0.053315584 | P9: Sharpe Ratio: | Q9: 0.053349553
A10: Return Adj. Close | B10: Squared Deviation | C10: Product of WFC and MSFT | D10: Return Adj. Close | E10: Squared Deviation | G10: 0.4 | H10: 0.6 | I10: =(G10*$B$5)+(H10*$E$5) -> 0.00069838032 | J10: =G10^2*$B$7^2+H10^2*$E$7^2+2*G10*H10*$C$7*$B$7*$E$7 -> 0.00017288299 | K10: =SQRT(G10^2*$B$7^2+H10^2*$E$7^2+2*G10*H10*$C$7*$B$7*$E$7) -> 0.013148498 | L10: =(I10-0)/K10 -> 0.053114837
G11: 0.45 | H11: 0.55 | I11: =(G11*$B$5)+(H11*$E$5) -> 0.00069231092 | J11: =G11^2*$B$7^2+H11^2*$E$7^2+2*G11*H11*$C$7*$B$7*$E$7 -> 0.00017237001 | K11: =SQRT(G11^2*$B$7^2+H11^2*$E$7^2+2*G11*H11*$C$7*$B$7*$E$7) -> 0.013128976 | L11: =(I11-0)/K11 -> 0.052731525
A12: -0.016406292 | B12: 0.00029008355 | C12: =A12*D12 -> -0.00010695071 | D12: 0.0065188837 | E12: 3.3315387e-05 | G12: 0.5 | H12: 0.5 | I12: =(G12*$B$5)+(H12*$E$5) -> 0.00068624152 | J12: =G12^2*$B$7^2+H12^2*$E$7^2+2*G12*H12*$C$7*$B$7*$E$7 -> 0.00017303991 | K12: =SQRT(G12^2*$B$7^2+H12^2*$E$7^2+2*G12*H12*$C$7*$B$7*$E$7) -> 0.013154463 | L12: =(I12-0)/K12 -> 0.05216796
A13: -0.011914262 | B13: 0.00015724681 | C13: =A13*D13 -> -5.6588143e-05 | D13: 0.004749614 | E13: 1.6021435e-05 | G13: 0.55 | H13: 0.45 | I13: =(G13*$B$5)+(H13*$E$5) -> 0.00068017213 | J13: =G13^2*$B$7^2+H13^2*$E$7^2+2*G13*H13*$C$7*$B$7*$E$7 -> 0.00017489269 | K13: =SQRT(G13^2*$B$7^2+H13^2*$E$7^2+2*G13*H13*$C$7*$B$7*$E$7) -> 0.0132247 | L13: =(I13-0)/K13 -> 0.051431952
A14: 0.010852135 | B14: 0.00010458309 | C14: =A14*D14 -> 0.00025649625 | D14: 0.023635556 | E14: 0.00052388894 | G14: 0.6 | H14: 0.4 | I14: =(G14*$B$5)+(H14*$E$5) -> 0.00067410273 | J14: =G14^2*$B$7^2+H14^2*$E$7^2+2*G14*H14*$C$7*$B$7*$E$7 -> 0.00017792835 | K14: =SQRT(G14^2*$B$7^2+H14^2*$E$7^2+2*G14*H14*$C$7*$B$7*$E$7) -> 0.013338979 | L14: =(I14-0)/K14 -> 0.050536308
A15: 0.060039782 | B15: 0.0035300513 | C15: =A15*D15 -> 0.0012098675 | D15: 0.020151098 | E15: 0.00037652152 | G15: 0.65 | H15: 0.35 | I15: =(G15*$B$5)+(H15*$E$5) -> 0.00066803333 | J15: =G15^2*$B$7^2+H15^2*$E$7^2+2*G15*H15*$C$7*$B$7*$E$7 -> 0.0001821469 | K15: =SQRT(G15^2*$B$7^2+H15^2*$E$7^2+2*G15*H15*$C$7*$B$7*$E$7) -> 0.013496181 | L15: =(I15-0)/K15 -> 0.049497953
A16: -0.00075024525 | B16: 1.8928059e-06 | C16: =A16*D16 -> -3.3962047e-06 | D16: 0.0045267926 | E16: 1.428732e-05 | G16: 0.7 | H16: 0.3 | I16: =(G16*$B$5)+(H16*$E$5) -> 0.00066196394 | J16: =G16^2*$B$7^2+H16^2*$E$7^2+2*G16*H16*$C$7*$B$7*$E$7 -> 0.00018754833 | K16: =SQRT(G16^2*$B$7^2+H16^2*$E$7^2+2*G16*H16*$C$7*$B$7*$E$7) -> 0.013694829 | L16: =(I16-0)/K16 -> 0.048336781
A17: 0.013513555 | B17: 0.00016610074 | C17: =A17*D17 -> -7.7504646e-05 | D17: -0.0057353261 | E17: 4.2019716e-05 | G17: 0.75 | H17: 0.25 | I17: =(G17*$B$5)+(H17*$E$5) -> 0.00065589454 | J17: =G17^2*$B$7^2+H17^2*$E$7^2+2*G17*H17*$C$7*$B$7*$E$7 -> 0.00019413264 | K17: =SQRT(G17^2*$B$7^2+H17^2*$E$7^2+2*G17*H17*$C$7*$B$7*$E$7) -> 0.013933149 | L17: =(I17-0)/K17 -> 0.047074393
A18: 0.0022222218 | B18: 2.5493688e-06 | C18: =A18*D18 -> 5.1274853e-05 | D18: 0.023073688 | E18: 0.00049848387 | G18: 0.8 | H18: 0.2 | I18: =(G18*$B$5)+(H18*$E$5) -> 0.00064982514 | J18: =G18^2*$B$7^2+H18^2*$E$7^2+2*G18*H18*$C$7*$B$7*$E$7 -> 0.00020189984 | K18: =SQRT(G18^2*$B$7^2+H18^2*$E$7^2+2*G18*H18*$C$7*$B$7*$E$7) -> 0.014209146 | L18: =(I18-0)/K18 -> 0.045732877
A19: 0.032520348 | B19: 0.0010172783 | C19: =A19*D19 -> 0.00039291629 | D19: 0.012082167 | E19: 0.00012848748 | G19: 0.85 | H19: 0.15 | I19: =(G19*$B$5)+(H19*$E$5) -> 0.00064375575 | J19: =G19^2*$B$7^2+H19^2*$E$7^2+2*G19*H19*$C$7*$B$7*$E$7 -> 0.00021084992 | K19: =SQRT(G19^2*$B$7^2+H19^2*$E$7^2+2*G19*H19*$C$7*$B$7*$E$7) -> 0.014520672 | L19: =(I19-0)/K19 -> 0.044333743
A20: -0.0100215 | B20: 0.00011335963 | C20: =A20*D20 -> -0.00012362393 | D20: 0.01233587 | E20: 0.00013430341 | G20: 0.9 | H20: 0.1 | I20: =(G20*$B$5)+(H20*$E$5) -> 0.00063768635 | J20: =G20^2*$B$7^2+H20^2*$E$7^2+2*G20*H20*$C$7*$B$7*$E$7 -> 0.00022098288 | K20: =SQRT(G20^2*$B$7^2+H20^2*$E$7^2+2*G20*H20*$C$7*$B$7*$E$7) -> 0.014865493 | L20: =(I20-0)/K20 -> 0.042897088
A21: 0.0054229926 | B21: 2.3015479e-05 | C21: =A21*D21 -> 1.4921809e-05 | D21: 0.002751582 | E21: 4.0186074e-06 | G21: 0.95 | H21: 0.05 | I21: =(G21*$B$5)+(H21*$E$5) -> 0.00063161695 | J21: =G21^2*$B$7^2+H21^2*$E$7^2+2*G21*H21*$C$7*$B$7*$E$7 -> 0.00023229872 | K21: =SQRT(G21^2*$B$7^2+H21^2*$E$7^2+2*G21*H21*$C$7*$B$7*$E$7) -> 0.015241349 | L21: =(I21-0)/K21 -> 0.041441013
A22: -0.056454531 | B22: 0.0032581354 | C22: =A22*D22 -> 0.0013720837 | D22: -0.024304226 | E22: 0.00062756071 | G22: 1 | H22: 0 | I22: =(G22*$B$5)+(H22*$E$5) -> 0.00062554756 | J22: =G22^2*$B$7^2+H22^2*$E$7^2+2*G22*H22*$C$7*$B$7*$E$7 -> 0.00024479745 | K22: =SQRT(G22^2*$B$7^2+H22^2*$E$7^2+2*G22*H22*$C$7*$B$7*$E$7) -> 0.015646004 | L22: =(I22-0)/K22 -> 0.039981298
A23: -0.0083840863 | B23: 8.1173503e-05 | C23: =A23*D23 -> -0.00011452745 | D23: 0.013660098 | E23: 0.00016674978 | Q23: Expected WFC | R23: Expected MSFT
A24: -0.0042275757 | B24: 2.3552805e-05 | C24: =A24*D24 -> -4.1890429e-05 | D24: 0.0099088536 | E24: 8.3940744e-05 | O24: Expected Portfolio Return: | P24: =((O30*$B$5)+(P30*$E$5)) -> 0.00070821168 | Q24: =O30*$B$5 -> 0.00019955515 | R24: =P30*$E$5 -> 0.00050865654
A25: 0.0057892697 | B25: 2.6664026e-05 | C25: =A25*D25 -> -8.179481e-05 | D25: -0.014128692 | E25: 0.0002212843 | O25: Variance of Port. Return: | P25: =O30^2*$B$7^2+P30^2*$E$7^2+2*O30*P30*$C$7*$B$7*$E$7 -> 0.00017622381
A26: 0.051036093 | B26: 0.0025412231 | C26: =A26*D26 -> 0.0014628165 | D26: 0.028662393 | E26: 0.00077927275 | O26: Std. Dev. Of Port. Return: | P26: =SQRT(O30^2*$B$7^2+P30^2*$E$7^2+2*O30*P30*$C$7*$B$7*$E$7) -> 0.013274932
A27: 0.0010952901 | B27: 2.2065803e-07 | C27: =A27*D27 -> -1.2716474e-06 | D27: -0.0011610143 | E27: 3.6402724e-06
A28: 0.017870151 | B28: 0.00029737634 | C28: =A28*D28 -> 0.00020078903 | D28: 0.011236001 | E28: 0.0001100205
A29: 0.017198134 | B29: 0.00027465063 | C29: =A29*D29 -> 3.9535192e-05 | D29: 0.002298807 | E29: 2.4083052e-06 | O29: Weight WFC | P29: Weight MSFT
A30: -0.011271546 | B30: 0.00014154083 | C30: =A30*D30 -> 9.0481895e-05 | D30: -0.0080274612 | E30: 7.6990037e-05 | O30: 0.31900875 | P30: 0.68099126
A31: -0.013537555 | B31: 0.00020059347 | C31: =A31*D31 -> -4.1733891e-05 | D31: 0.0030828234 | E31: 5.4563724e-06
A32: 0.0014445088 | B32: 6.7069756e-07 | C32: =A32*D32 -> -1.2208732e-05 | D32: -0.0084518224 | E32: 8.4617146e-05 | O32: Total Investment
A33: 0.030292098 | B33: 0.0008801042 | C33: =A33*D33 -> 0.00061030322 | D33: 0.020147275 | E33: 0.00037637316 | O33: =SUM(O30:P30) -> 1 | P33: = | Q33: 1
A34: -0.015750745 | B34: 0.00026818295 | C34: =A34*D34 -> 0.00010169555 | D34: -0.0064565551 | E34: 5.1890277e-05
A35: -0.0049875606 | B35: 3.1506983e-05 | C35: =A35*D35 -> 8.1981946e-05 | D35: -0.016437283 | E35: 0.00029529737 | O35: Sharpe Ratio
A36: -0.0017902447 | B36: 5.8360521e-06 | C36: =A36*D36 -> 2.5048054e-05 | D36: -0.013991414 | E36: 0.00021721893 | O36: =(P24-0)/P26 -> 0.053349553
A37: -0.004662777 | B37: 2.7966376e-05 | C37: =A37*D37 -> -3.3081964e-05 | D37: 0.0070949059 | E37: 4.0296729e-05
A38: 0.017297287 | B38: 0.00027794689 | C38: =A38*D38 -> 4.0621476e-05 | D38: 0.0023484305 | E38: 2.5647863e-06
A39: -0.01629469 | B39: 0.00028629444 | C39: =A39*D39 -> 0.00034358288 | D39: -0.021085573 | E39: 0.00047665843
A40: -0.052934864 | B40: 0.0028687177 | C40: =A40*D40 -> 0.00044341038 | D40: -0.0083765282 | E40: 8.3237589e-05
...

Sheet 10_Stock_Port
F2: Correlation Table | T2: Expected Individual
A3: Assets | B3: AAPL | C3: BIDU | D3: COP | E3: DIS | F3: GOOG | G3: TSLA | H3: TTM | I3: XOM | J3: MSFT | K3: WFC | P3: AAPL | Q3: BIDU | R3: COP | S3: DIS | T3: GOOG | U3: TSLA | V3: TTM | W3: XOM | X3: MSFT | Y3: WFC
A4: AAPL | B4: =CORREL(AAPL!$J$4:$J$1514,AAPL!$J$4:$J$1514) -> 1 | C4: =CORREL(AAPL!$J$4:$J$1514,BIDU!$J$4:$J$1514) -> 0.34059191 | D4: =CORREL(AAPL!$J$4:$J$1514,COP!$J$4:$J$1514) -> 0.31225933 | E4: =CORREL(AAPL!$J$4:$J$1514,DIS!$J$4:$J$1514) -> 0.35219374 | F4: =CORREL(AAPL!$J$4:$J$1514,GOOG!$J$4:$J$1514) -> 0.39138217 | G4: =CORREL(AAPL!$J$4:$J$1514,TSLA!$J$4:$J$1514) -> 0.2192821 | H4: =CORREL(AAPL!$J$4:$J$1514,TTM!$J$4:$J$1514) -> 0.30801675 | I4: =CORREL(AAPL!$J$4:$J$1514,XOM!$J$4:$J$1514) -> 0.34238405 | J4: =CORREL(AAPL!$J$4:$J$1514,MSFT!$J$4:$J$1514) -> 0.372886 | K4: =CORREL(WFC!$J$4:$J$1514,AAPL!$J$4:$J$1514) -> 0.38541828 | M4: Expected Portfolio Return: | N4: =((P10*B31)+(Q10*C31)+(R10*D31)+(S10*E31)+(T10*F31)+(U10*G31)+(V10*H31)+(W10*I31)+(X10*J31)+(Y10*K31)) -> 0.0010586116 | P4: =P10*B31 -> 0.00014334255 | Q4: =Q10*C31 -> 0 | R4: =R10*D31 -> 0 | S4: =S10*E31 -> 0.00034824592 | T4: =T10*F31 -> 0.00015344317 | U4: =U10*G31 -> 0.00033950455 | V4: =V10*H31 -> 0 | W4: =W10*I31 -> 0 | ... Y4: =Y10*K31 -> 0
A5: BIDU | B5: =CORREL(AAPL!$J$4:$J$1514,BIDU!$J$4:$J$1514) -> 0.34059191 | C5: =CORREL(BIDU!$J$4:$J$1514,BIDU!$J$4:$J$1514) -> 1 | D5: =CORREL(BIDU!$J$4:$J$1514,COP!$J$4:$J$1514) -> 0.3250151 | E5: =CORREL(BIDU!$J$4:$J$1514,DIS!$J$4:$J$1514) -> 0.38201275 | F5: =CORREL(BIDU!$J$4:$J$1514,GOOG!$J$4:$J$1514) -> 0.42843031 | G5: =CORREL(BIDU!$J$4:$J$1514,TSLA!$J$4:$J$1514) -> 0.25009529 | H5: =CORREL(BIDU!$J$4:$J$1514,TTM!$J$4:$J$1514) -> 0.35752369 | I5: =CORREL(BIDU!$J$4:$J$1514,XOM!$J$4:$J$1514) -> 0.32846344 | J5: =CORREL(BIDU!$J$4:$J$1514,MSFT!$J$4:$J$1514) -> 0.34159745 | K5: =CORREL(WFC!$J$4:$J$1514,BIDU!$J$4:$J$1514) -> 0.39688038 | M5: Variance of Port. Return: | N5: {=MMULT(MMULT(TRANSPOSE(P10:P19), B18:K27),P10:P19)} -> 0.00015822111
A6: COP | B6: =CORREL(AAPL!$J$4:$J$1514,COP!$J$4:$J$1514) -> 0.31225933 | C6: =CORREL(BIDU!$J$4:$J$1514,COP!$J$4:$J$1514) -> 0.3250151 | D6: =CORREL(COP!$J$4:$J$1514,COP!$J$4:$J$1514) -> 1 | E6: =CORREL(COP!$J$4:$J$1514,DIS!$J$4:$J$1514) -> 0.44164943 | F6: =CORREL(COP!$J$4:$J$1514,GOOG!$J$4:$J$1514) -> 0.32336098 | G6: =CORREL(COP!$J$4:$J$1514,TSLA!$J$4:$J$1514) -> 0.24470081 | H6: =CORREL(COP!$J$4:$J$1514,TTM!$J$4:$J$1514) -> 0.37625757 | I6: =CORREL(COP!$J$4:$J$1514,XOM!$J$4:$J$1514) -> 0.71384857 | J6: =CORREL(COP!$J$4:$J$1514,MSFT!$J$4:$J$1514) -> 0.38605774 | K6: =CORREL(WFC!$J$4:$J$1514,COP!$J$4:$J$1514) -> 0.50261224 | M6: Std. Dev. Of Port. Return: | N6: =SQRT(N5) -> 0.012578597
A7: DIS | B7: =CORREL(AAPL!$J$4:$J$1514,DIS!$J$4:$J$1514) -> 0.35219374 | C7: =CORREL(BIDU!$J$4:$J$1514,DIS!$J$4:$J$1514) -> 0.38201275 | D7: =CORREL(COP!$J$4:$J$1514,DIS!$J$4:$J$1514) -> 0.44164943 | E7: =CORREL(DIS!$J$4:$J$1514,DIS!$J$4:$J$1514) -> 1 | F7: =CORREL(DIS!$J$4:$J$1514,GOOG!$J$4:$J$1514) -> 0.41792868 | G7: =CORREL(DIS!$J$4:$J$1514,TSLA!$J$4:$J$1514) -> 0.28015546 | H7: =CORREL(DIS!$J$4:$J$1514,TTM!$J$4:$J$1514) -> 0.40903119 | I7: =CORREL(DIS!$J$4:$J$1514,XOM!$J$4:$J$1514) -> 0.53572779 | J7: =CORREL(DIS!$J$4:$J$1514,MSFT!$J$4:$J$1514) -> 0.45984151 | K7: =CORREL(WFC!$J$4:$J$1514,DIS!$J$4:$J$1514) -> 0.61159054
A8: GOOG | B8: =CORREL(AAPL!$J$4:$J$1514,GOOG!$J$4:$J$1514) -> 0.39138217 | C8: =CORREL(BIDU!$J$4:$J$1514,GOOG!$J$4:$J$1514) -> 0.42843031 | D8: =CORREL(COP!$J$4:$J$1514,GOOG!$J$4:$J$1514) -> 0.32336098 | E8: =CORREL(DIS!$J$4:$J$1514,GOOG!$J$4:$J$1514) -> 0.41792868 | F8: =CORREL(GOOG!$J$4:$J$1514,GOOG!$J$4:$J$1514) -> 1 | G8: =CORREL(GOOG!$J$4:$J$1514,TSLA!$J$4:$J$1514) -> 0.24628095 | H8: =CORREL(GOOG!$J$4:$J$1514,TTM!$J$4:$J$1514) -> 0.29939438 | I8: =CORREL(GOOG!$J$4:$J$1514,XOM!$J$4:$J$1514) -> 0.3900213 | J8: =CORREL(GOOG!$J$4:$J$1514,MSFT!$J$4:$J$1514) -> 0.45493459 | K8: =CORREL(WFC!$J$4:$J$1514,GOOG!$J$4:$J$1514) -> 0.43170725 | M8: Total Investment | T8: Weights
A9: TSLA | B9: =CORREL(AAPL!$J$4:$J$1514,TSLA!$J$4:$J$1514) -> 0.2192821 | C9: =CORREL(BIDU!$J$4:$J$1514,TSLA!$J$4:$J$1514) -> 0.25009529 | D9: =CORREL(COP!$J$4:$J$1514,TSLA!$J$4:$J$1514) -> 0.24470081 | E9: =CORREL(DIS!$J$4:$J$1514,TSLA!$J$4:$J$1514) -> 0.28015546 | F9: =CORREL(GOOG!$J$4:$J$1514,TSLA!$J$4:$J$1514) -> 0.24628095 | G9: =CORREL(TSLA!$J$4:$J$1514,TSLA!$J$4:$J$1514) -> 1 | H9: =CORREL(TSLA!$J$4:$J$1514,TTM!$J$4:$J$1514) -> 0.26224132 | I9: =CORREL(TSLA!$J$4:$J$1514,XOM!$J$4:$J$1514) -> 0.23793303 | J9: =CORREL(TSLA!$J$4:$J$1514,MSFT!$J$4:$J$1514) -> 0.22541166 | K9: =CORREL(WFC!$J$4:$J$1514,TSLA!$J$4:$J$1514) -> 0.25599649 | M9: =SUM(P10:Y10) -> 1 | O9: Assets | P9: AAPL | Q9: BIDU | R9: COP | S9: DIS | T9: GOOG | U9: TSLA | V9: TTM | W9: XOM | X9: MSFT | Y9: WFC
A10: TTM | B10: =CORREL(AAPL!$J$4:$J$1514,TTM!$J$4:$J$1514) -> 0.30801675 | C10: =CORREL(BIDU!$J$4:$J$1514,TTM!$J$4:$J$1514) -> 0.35752369 | D10: =CORREL(COP!$J$4:$J$1514,TTM!$J$4:$J$1514) -> 0.37625757 | E10: =CORREL(DIS!$J$4:$J$1514,TTM!$J$4:$J$1514) -> 0.40903119 | F10: =CORREL(GOOG!$J$4:$J$1514,TTM!$J$4:$J$1514) -> 0.29939438 | G10: =CORREL(TSLA!$J$4:$J$1514,TTM!$J$4:$J$1514) -> 0.26224132 | H10: =CORREL(TTM!$J$4:$J$1514,TTM!$J$4:$J$1514) -> 1 | I10: =CORREL(TTM!$J$4:$J$1514,XOM!$J$4:$J$1514) -> 0.39936788 | J10: =CORREL(TTM!$J$4:$J$1514,MSFT!$J$4:$J$1514) -> 0.36391912 | K10: =CORREL(WFC!$J$4:$J$1514,TTM!$J$4:$J$1514) -> 0.44517293 | M10: = | O10: AAPL | P10: 0.17078945 | Q10: =P11 -> 0 | R10: =P12 -> 0 | S10: =P13 -> 0.38792701 | T10: =P14 -> 0.17471439 | U10: =P15 -> 0.16739666 | V10: =P16 -> 0 | W10: =P17 -> 0 | X10: =P18 -> 0.099172501 | Y10: =P19 -> 0
A11: XOM | B11: =CORREL(AAPL!$J$4:$J$1514,XOM!$J$4:$J$1514) -> 0.34238405 | C11: =CORREL(BIDU!$J$4:$J$1514,XOM!$J$4:$J$1514) -> 0.32846344 | D11: =CORREL(COP!$J$4:$J$1514,XOM!$J$4:$J$1514) -> 0.71384857 | E11: =CORREL(DIS!$J$4:$J$1514,XOM!$J$4:$J$1514) -> 0.53572779 | F11: =CORREL(GOOG!$J$4:$J$1514,XOM!$J$4:$J$1514) -> 0.3900213 | G11: =CORREL(TSLA!$J$4:$J$1514,XOM!$J$4:$J$1514) -> 0.23793303 | H11: =CORREL(TTM!$J$4:$J$1514,XOM!$J$4:$J$1514) -> 0.39936788 | I11: =CORREL(XOM!$J$4:$J$1514,XOM!$J$4:$J$1514) -> 1 | J11: =CORREL(XOM!$J$4:$J$1514,MSFT!$J$4:$J$1514) -> 0.46000772 | K11: =CORREL(WFC!$J$4:$J$1514,XOM!$J$4:$J$1514) -> 0.58875307 | M11: 1 | O11: BIDU | P11: 0
A12: MSFT | B12: =CORREL(AAPL!$J$4:$J$1514,MSFT!$J$4:$J$1514) -> 0.372886 | C12: =CORREL(BIDU!$J$4:$J$1514,MSFT!$J$4:$J$1514) -> 0.34159745 | D12: =CORREL(COP!$J$4:$J$1514,MSFT!$J$4:$J$1514) -> 0.38605774 | E12: =CORREL(DIS!$J$4:$J$1514,MSFT!$J$4:$J$1514) -> 0.45984151 | F12: =CORREL(GOOG!$J$4:$J$1514,MSFT!$J$4:$J$1514) -> 0.45493459 | G12: =CORREL(TSLA!$J$4:$J$1514,MSFT!$J$4:$J$1514) -> 0.22541166 | H12: =CORREL(TTM!$J$4:$J$1514,MSFT!$J$4:$J$1514) -> 0.36391912 | I12: =CORREL(XOM!$J$4:$J$1514,MSFT!$J$4:$J$1514) -> 0.46000772 | J12: =CORREL(MSFT!$J$4:$J$1514,MSFT!$J$4:$J$1514) -> 1 | K12: =CORREL(WFC!$J$4:$J$1514,MSFT!$J$4:$J$1514) -> 0.49159166 | O12: COP | P12: 0
A13: WFC | B13: =CORREL(WFC!$J$4:$J$1514,AAPL!$J$4:$J$1514) -> 0.38541828 | C13: =CORREL(WFC!$J$4:$J$1514,BIDU!$J$4:$J$1514) -> 0.39688038 | D13: =CORREL(WFC!$J$4:$J$1514,COP!$J$4:$J$1514) -> 0.50261224 | E13: =CORREL(WFC!$J$4:$J$1514,DIS!$J$4:$J$1514) -> 0.61159054 | F13: =CORREL(WFC!$J$4:$J$1514,GOOG!$J$4:$J$1514) -> 0.43170725 | G13: =CORREL(WFC!$J$4:$J$1514,TSLA!$J$4:$J$1514) -> 0.25599649 | H13: =CORREL(WFC!$J$4:$J$1514,TTM!$J$4:$J$1514) -> 0.44517293 | I13: =CORREL(WFC!$J$4:$J$1514,XOM!$J$4:$J$1514) -> 0.58875307 | J13: =CORREL(WFC!$J$4:$J$1514,MSFT!$J$4:$J$1514) -> 0.49159166 | K13: =CORREL(WFC!$J$4:$J$1514,WFC!$J$4:$J$1514) -> 1 | M13: Sharpe Ratio | O13: DIS | P13: 0.38792701
M14: =(N4-0)/N6 -> 0.084159754 | O14: GOOG | P14: 0.17471439
O15: TSLA | P15: 0.16739666
F16: Covariance Table | O16: TTM | P16: 0
A17: Assets | B17: AAPL | C17: BIDU | D17: COP | E17: DIS | F17: GOOG | G17: TSLA | H17: TTM | I17: XOM | J17: MSFT | K17: WFC | O17: XOM | P17: 0
A18: AAPL | B18: =_xlfn.COVARIANCE.S(AAPL!$J$4:$J$1514,AAPL!$J$4:$J$1514) -> 0.00027278234 | C18: =_xlfn.COVARIANCE.S(AAPL!$J$4:$J$1514,BIDU!$J$4:$J$1514) -> 0.00014029648 | D18: =_xlfn.COVARIANCE.S(AAPL!$J$4:$J$1514,COP!$J$4:$J$1514) -> 8.6453503e-05 | E18: =_xlfn.COVARIANCE.S(AAPL!$J$4:$J$1514,DIS!$J$4:$J$1514) -> 7.9886233e-05 | F18: =_xlfn.COVARIANCE.S(AAPL!$J$4:$J$1514,GOOG!$J$4:$J$1514) -> 0.00010341452 | G18: =_xlfn.COVARIANCE.S(AAPL!$J$4:$J$1514,TSLA!$J$4:$J$1514) -> 0.00012392717 | H18: =_xlfn.COVARIANCE.S(AAPL!$J$4:$J$1514,TTM!$J$4:$J$1514) -> 0.00012632988 | I18: =_xlfn.COVARIANCE.S(AAPL!$J$4:$J$1514,XOM!$J$4:$J$1514) -> 6.772234e-05 | J18: =_xlfn.COVARIANCE.S(AAPL!$J$4:$J$1514,MSFT!$J$4:$J$1514) -> 9.1258085e-05 | K18: =_xlfn.COVARIANCE.S(WFC!$J$4:$J$1514,AAPL!$J$4:$J$1514) -> 9.9596454e-05 | O18: MSFT | P18: 0.099172501
A19: BIDU | B19: =_xlfn.COVARIANCE.S(AAPL!$J$4:$J$1514,BIDU!$J$4:$J$1514) -> 0.00014029648 | C19: =_xlfn.COVARIANCE.S(BIDU!$J$4:$J$1514,BIDU!$J$4:$J$1514) -> 0.00062202616 | D19: =_xlfn.COVARIANCE.S(BIDU!$J$4:$J$1514,COP!$J$4:$J$1514) -> 0.00013588355 | E19: =_xlfn.COVARIANCE.S(BIDU!$J$4:$J$1514,DIS!$J$4:$J$1514) -> 0.00013084718 | F19: =_xlfn.COVARIANCE.S(BIDU!$J$4:$J$1514,GOOG!$J$4:$J$1514) -> 0.00017094518 | G19: =_xlfn.COVARIANCE.S(BIDU!$J$4:$J$1514,TSLA!$J$4:$J$1514) -> 0.00021343472 | H19: =_xlfn.COVARIANCE.S(BIDU!$J$4:$J$1514,TTM!$J$4:$J$1514) -> 0.00022142811 | I19: =_xlfn.COVARIANCE.S(BIDU!$J$4:$J$1514,XOM!$J$4:$J$1514) -> 9.8107378e-05 | J19: =_xlfn.COVARIANCE.S(BIDU!$J$4:$J$1514,MSFT!$J$4:$J$1514) -> 0.00012624264 | K19: =_xlfn.COVARIANCE.S(WFC!$J$4:$J$1514,BIDU!$J$4:$J$1514) -> 0.00015487003 | O19: WFC | P19: 0
A20: COP | B20: =_xlfn.COVARIANCE.S(AAPL!$J$4:$J$1514,COP!$J$4:$J$1514) -> 8.6453503e-05 | C20: =_xlfn.COVARIANCE.S(BIDU!$J$4:$J$1514,COP!$J$4:$J$1514) -> 0.00013588355 | D20: =_xlfn.COVARIANCE.S(COP!$J$4:$J$1514,COP!$J$4:$J$1514) -> 0.0002810076 | E20: =_xlfn.COVARIANCE.S(COP!$J$4:$J$1514,DIS!$J$4:$J$1514) -> 0.0001016761 | F20: =_xlfn.COVARIANCE.S(COP!$J$4:$J$1514,GOOG!$J$4:$J$1514) -> 8.6719946e-05 | G20: =_xlfn.COVARIANCE.S(COP!$J$4:$J$1514,TSLA!$J$4:$J$1514) -> 0.00014036204 | H20: =_xlfn.COVARIANCE.S(COP!$J$4:$J$1514,TTM!$J$4:$J$1514) -> 0.00015662746 | I20: =_xlfn.COVARIANCE.S(COP!$J$4:$J$1514,XOM!$J$4:$J$1514) -> 0.00014330965 | J20: =_xlfn.COVARIANCE.S(COP!$J$4:$J$1514,MSFT!$J$4:$J$1514) -> 9.5895547e-05 | K20: =_xlfn.COVARIANCE.S(WFC!$J$4:$J$1514,COP!$J$4:$J$1514) -> 0.00013182432
A21: DIS | B21: =_xlfn.COVARIANCE.S(AAPL!$J$4:$J$1514,DIS!$J$4:$J$1514) -> 7.9886233e-05 | C21: =_xlfn.COVARIANCE.S(BIDU!$J$4:$J$1514,DIS!$J$4:$J$1514) -> 0.00013084718 | D21: =_xlfn.COVARIANCE.S(COP!$J$4:$J$1514,DIS!$J$4:$J$1514) -> 0.0001016761 | E21: =_xlfn.COVARIANCE.S(DIS!$J$4:$J$1514,DIS!$J$4:$J$1514) -> 0.00018860985 | F21: =_xlfn.COVARIANCE.S(DIS!$J$4:$J$1514,GOOG!$J$4:$J$1514) -> 9.1824107e-05 | G21: =_xlfn.COVARIANCE.S(DIS!$J$4:$J$1514,TSLA!$J$4:$J$1514) -> 0.00013165474 | H21: =_xlfn.COVARIANCE.S(DIS!$J$4:$J$1514,TTM!$J$4:$J$1514) -> 0.00013949615 | I21: =_xlfn.COVARIANCE.S(DIS!$J$4:$J$1514,XOM!$J$4:$J$1514) -> 8.8112327e-05 | J21: =_xlfn.COVARIANCE.S(DIS!$J$4:$J$1514,MSFT!$J$4:$J$1514) -> 9.3578806e-05 | K21: =_xlfn.COVARIANCE.S(WFC!$J$4:$J$1514,DIS!$J$4:$J$1514) -> 0.00013141544
A22: GOOG | B22: =_xlfn.COVARIANCE.S(AAPL!$J$4:$J$1514,GOOG!$J$4:$J$1514) -> 0.00010341452 | C22: =_xlfn.COVARIANCE.S(BIDU!$J$4:$J$1514,GOOG!$J$4:$J$1514) -> 0.00017094518 | D22: =_xlfn.COVARIANCE.S(COP!$J$4:$J$1514,GOOG!$J$4:$J$1514) -> 8.6719946e-05 | E22: =_xlfn.COVARIANCE.S(DIS!$J$4:$J$1514,GOOG!$J$4:$J$1514) -> 9.1824107e-05 | F22: =_xlfn.COVARIANCE.S(GOOG!$J$4:$J$1514,GOOG!$J$4:$J$1514) -> 0.00025594385 | G22: =_xlfn.COVARIANCE.S(GOOG!$J$4:$J$1514,TSLA!$J$4:$J$1514) -> 0.00013482127 | H22: =_xlfn.COVARIANCE.S(GOOG!$J$4:$J$1514,TTM!$J$4:$J$1514) -> 0.0001189432 | I22: =_xlfn.COVARIANCE.S(GOOG!$J$4:$J$1514,XOM!$J$4:$J$1514) -> 7.4725871e-05 | J22: =_xlfn.COVARIANCE.S(GOOG!$J$4:$J$1514,MSFT!$J$4:$J$1514) -> 0.00010784709 | K22: =_xlfn.COVARIANCE.S(WFC!$J$4:$J$1514,GOOG!$J$4:$J$1514) -> 0.00010806004
A23: TSLA | B23: =_xlfn.COVARIANCE.S(AAPL!$J$4:$J$1514,TSLA!$J$4:$J$1514) -> 0.00012392717 | C23: =_xlfn.COVARIANCE.S(BIDU!$J$4:$J$1514,TSLA!$J$4:$J$1514) -> 0.00021343472 | D23: =_xlfn.COVARIANCE.S(COP!$J$4:$J$1514,TSLA!$J$4:$J$1514) -> 0.00014036204 | E23: =_xlfn.COVARIANCE.S(DIS!$J$4:$J$1514,TSLA!$J$4:$J$1514) -> 0.00013165474 | F23: =_xlfn.COVARIANCE.S(GOOG!$J$4:$J$1514,TSLA!$J$4:$J$1514) -> 0.00013482127 | G23: =_xlfn.COVARIANCE.S(TSLA!$J$4:$J$1514,TSLA!$J$4:$J$1514) -> 0.0011708748 | H23: =_xlfn.COVARIANCE.S(TSLA!$J$4:$J$1514,TTM!$J$4:$J$1514) -> 0.00022283324 | I23: =_xlfn.COVARIANCE.S(TSLA!$J$4:$J$1514,XOM!$J$4:$J$1514) -> 9.7503516e-05 | J23: =_xlfn.COVARIANCE.S(TSLA!$J$4:$J$1514,MSFT!$J$4:$J$1514) -> 0.00011429277 | K23: =_xlfn.COVARIANCE.S(WFC!$J$4:$J$1514,TSLA!$J$4:$J$1514) -> 0.00013705431 | M23: Tangent Portfolio Plot | O23: Asset\Char. | P23: Weights | Q23: Ex. Return
A24: TTM | B24: =_xlfn.COVARIANCE.S(AAPL!$J$4:$J$1514,TTM!$J$4:$J$1514) -> 0.00012632988 | C24: =_xlfn.COVARIANCE.S(BIDU!$J$4:$J$1514,TTM!$J$4:$J$1514) -> 0.00022142811 | D24: =_xlfn.COVARIANCE.S(COP!$J$4:$J$1514,TTM!$J$4:$J$1514) -> 0.00015662746 | E24: =_xlfn.COVARIANCE.S(DIS!$J$4:$J$1514,TTM!$J$4:$J$1514) -> 0.00013949615 | F24: =_xlfn.COVARIANCE.S(GOOG!$J$4:$J$1514,TTM!$J$4:$J$1514) -> 0.0001189432 | G24: =_xlfn.COVARIANCE.S(TSLA!$J$4:$J$1514,TTM!$J$4:$J$1514) -> 0.00022283324 | H24: =_xlfn.COVARIANCE.S(TTM!$J$4:$J$1514,TTM!$J$4:$J$1514) -> 0.00061666206 | I24: =_xlfn.COVARIANCE.S(TTM!$J$4:$J$1514,XOM!$J$4:$J$1514) -> 0.00011877008 | J24: =_xlfn.COVARIANCE.S(TTM!$J$4:$J$1514,MSFT!$J$4:$J$1514) -> 0.00013391081 | K24: =_xlfn.COVARIANCE.S(WFC!$J$4:$J$1514,TTM!$J$4:$J$1514) -> 0.00017296403 | O24: AAPL | P24: 0.20654928 | Q24: 0.00017335556
A25: XOM | B25: =_xlfn.COVARIANCE.S(AAPL!$J$4:$J$1514,XOM!$J$4:$J$1514) -> 6.772234e-05 | C25: =_xlfn.COVARIANCE.S(BIDU!$J$4:$J$1514,XOM!$J$4:$J$1514) -> 9.8107378e-05 | D25: =_xlfn.COVARIANCE.S(COP!$J$4:$J$1514,XOM!$J$4:$J$1514) -> 0.00014330965 | E25: =_xlfn.COVARIANCE.S(DIS!$J$4:$J$1514,XOM!$J$4:$J$1514) -> 8.8112327e-05 | F25: =_xlfn.COVARIANCE.S(GOOG!$J$4:$J$1514,XOM!$J$4:$J$1514) -> 7.4725871e-05 | G25: =_xlfn.COVARIANCE.S(TSLA!$J$4:$J$1514,XOM!$J$4:$J$1514) -> 9.7503516e-05 | H25: =_xlfn.COVARIANCE.S(TTM!$J$4:$J$1514,XOM!$J$4:$J$1514) -> 0.00011877008 | I25: =_xlfn.COVARIANCE.S(XOM!$J$4:$J$1514,XOM!$J$4:$J$1514) -> 0.0001434236 | J25: =_xlfn.COVARIANCE.S(XOM!$J$4:$J$1514,MSFT!$J$4:$J$1514) -> 8.16324e-05 | K25: =_xlfn.COVARIANCE.S(WFC!$J$4:$J$1514,XOM!$J$4:$J$1514) -> 0.00011031814 | M25: Risk-Free Rate: | N25: 0 | O25: BIDU | P25: -0.015010852 | Q25: -1.3467683e-05
A26: MSFT | B26: =_xlfn.COVARIANCE.S(AAPL!$J$4:$J$1514,MSFT!$J$4:$J$1514) -> 9.1258085e-05 | C26: =_xlfn.COVARIANCE.S(BIDU!$J$4:$J$1514,MSFT!$J$4:$J$1514) -> 0.00012624264 | D26: =_xlfn.COVARIANCE.S(COP!$J$4:$J$1514,MSFT!$J$4:$J$1514) -> 9.5895547e-05 | E26: =_xlfn.COVARIANCE.S(DIS!$J$4:$J$1514,MSFT!$J$4:$J$1514) -> 9.3578806e-05 | F26: =_xlfn.COVARIANCE.S(GOOG!$J$4:$J$1514,MSFT!$J$4:$J$1514) -> 0.00010784709 | G26: =_xlfn.COVARIANCE.S(TSLA!$J$4:$J$1514,MSFT!$J$4:$J$1514) -> 0.00011429277 | H26: =_xlfn.COVARIANCE.S(TTM!$J$4:$J$1514,MSFT!$J$4:$J$1514) -> 0.00013391081 | I26: =_xlfn.COVARIANCE.S(XOM!$J$4:$J$1514,MSFT!$J$4:$J$1514) -> 8.16324e-05 | J26: =_xlfn.COVARIANCE.S(MSFT!$J$4:$J$1514,MSFT!$J$4:$J$1514) -> 0.00021957065 | K26: =_xlfn.COVARIANCE.S(WFC!$J$4:$J$1514,MSFT!$J$4:$J$1514) -> 0.00011397119 | M26: Expected Returns: | N26: =N29*N28 -> 0.001147494 | O26: COP | P26: -0.2457373 | Q26: -9.8987715e-05
A27: WFC | B27: =_xlfn.COVARIANCE.S(WFC!$J$4:$J$1514,AAPL!$J$4:$J$1514) -> 9.9596454e-05 | C27: =_xlfn.COVARIANCE.S(WFC!$J$4:$J$1514,BIDU!$J$4:$J$1514) -> 0.00015487003 | D27: =_xlfn.COVARIANCE.S(WFC!$J$4:$J$1514,COP!$J$4:$J$1514) -> 0.00013182432 | E27: =_xlfn.COVARIANCE.S(WFC!$J$4:$J$1514,DIS!$J$4:$J$1514) -> 0.00013141544 | F27: =_xlfn.COVARIANCE.S(WFC!$J$4:$J$1514,GOOG!$J$4:$J$1514) -> 0.00010806004 | G27: =_xlfn.COVARIANCE.S(WFC!$J$4:$J$1514,TSLA!$J$4:$J$1514) -> 0.00013705431 | H27: =_xlfn.COVARIANCE.S(WFC!$J$4:$J$1514,TTM!$J$4:$J$1514) -> 0.00017296403 | I27: =_xlfn.COVARIANCE.S(WFC!$J$4:$J$1514,XOM!$J$4:$J$1514) -> 0.00011031814 | J27: =_xlfn.COVARIANCE.S(WFC!$J$4:$J$1514,MSFT!$J$4:$J$1514) -> 0.00011397119 | K27: =_xlfn.COVARIANCE.S(WFC!$J$4:$J$1514,WFC!$J$4:$J$1514) -> 0.00024479745 | M27: Variance : | N27: 0.00017019569 | O27: DIS | P27: 0.49699024 | Q27: 0.00044615306
M28: Standard deviations: | N28: 0.013045907 | O28: GOOG | P28: 0.20095099 | Q28: 0.00017648551
M29: Sharpe Ratio: | N29: 0.087958161 | O29: TSLA | P29: 0.17946375 | Q29: 0.00036397834
A30: Stats.\Assets | B30: AAPL | C30: BIDU | D30: COP | E30: DIS | F30: GOOG | G30: TSLA | H30: TTM | I30: XOM | J30: MSFT | K30: WFC | O30: TTM | P30: -0.021101396 | Q30: -1.7194071e-05
A31: Mean | B31: 0.00083929393 | C31: 0.00089719644 | D31: 0.00040281925 | E31: 0.0008977099 | F31: 0.00087825152 | G31: 0.0020281441 | H31: 0.00081483095 | I31: 0.00051131218 | J31: 0.00074693549 | K31: 0.00062554756 | O31: XOM | P31: 0.21982543 | Q31: 0.00011239942
A32: Std. Deviation | B32: 0.016516124 | C32: 0.024940452 | D32: 0.016763281 | E32: 0.01373353 | F32: 0.015998245 | G32: 0.034218048 | H32: 0.024832681 | I32: 0.011975959 | J32: 0.014817916 | K32: 0.015646004 | O32: MSFT | P32: 0.15232084 | Q32: 0.00011377384
O33: WFC | P33: -0.17425099 | Q33: -0.00010900228

Sheet CAPM
A1: AAPL | B1: BIDU | C1: COP | D1: DIS | E1: GOOG | F1: TSLA | G1: TTM | H1: XOM | I1: MSFT | J1: WFC | K1: DJI
A2: -0.012125807 | B2: 0.0069036573 | C2: -0.0044815707 | D2: -0.00031746476 | E2: -0.012271026 | F2: -0.078472556 | G2: 0.011052902 | H2: -0.008060274 | I2: 0.0065188837 | J2: -0.016406292 | K2: -0.0042448511
A3: -0.006197722 | B3: -0.014587891 | C3: -0.0010232382 | D3: -0.0034931867 | E3: -0.0066896311 | F3: -0.12568297 | G3: -0.012658201 | H3: -0.00070660504 | I3: 0.004749614 | J3: -0.011914262 | K3: -0.0047315346 | M3: AAPL | W3: TSLA
A4: 0.0068437567 | B4: -0.0014804737 | C4: 0.0077837007 | D4: 0.010834939 | E4: -0.0010994678 | F4: -0.16093749 | G4: 0.0064103046 | H4: 0.015732713 | I4: 0.023635556 | J4: 0.010852135 | K4: 0.0058989071
A5: 0.04038137 | B5: 0.072943013 | C5: 0.039837604 | D5: 0.044766682 | E5: 0.032402993 | F5: -0.019242767 | G5: 0.0017370002 | H5: 0.016881334 | I5: 0.020151098 | J5: 0.060039782 | K5: 0.028188717 | M5: Regression Statistics | W5: Regression Statistics
A6: -0.0022423051 | B6: 0.00082903133 | C6: 0.0076231097 | D6: 0.0060350547 | E6: 0.01412711 | F6: 0.10506323 | G6: 0.015028926 | H6: 0.0065035149 | I6: 0.0045267926 | J6: -0.00075024525 | K6: 0.01204897 | M6: Multiple R | N6: 0.49649556 | W6: Multiple R | X6: 0.32991253
A7: 0.0059281733 | B7: -0.016981955 | C7: 0.014549026 | D7: 0.012297516 | E7: 0.023939842 | F7: -0.003436369 | G7: 0.0051253069 | H7: -0.00051015912 | I7: -0.0057353261 | J7: 0.013513555 | K7: 0.005823069 | M7: R Square | N7: 0.24650784 | W7: R Square | X7: 0.10884228
A8: -0.0089746265 | B8: -0.0066010396 | C8: -0.0038242342 | D8: 0.00059260089 | E8: 0.017839983 | F8: -0.020115 | G8: 0.0090651143 | H8: 0.002722016 | I8: 0.023073688 | J8: 0.0022222218 | K8: 0.0017885081 | M8: Adjusted R Square | N8: 0.24600851 | W8: Adjusted R Square | X8: 0.10825172
A9: -0.021337814 | B9: 0.051604607 | C9: 0.021497304 | D9: 0.020136239 | E9: 0.028098257 | F9: 0.063929623 | G9: 0.039865318 | H9: 0.0081438803 | I9: 0.012082167 | J9: 0.032520348 | K9: 0.014364343 | M9: Standard Error | N9: 0.014341393 | W9: Standard Error | X9: 0.032312933
A10: 0.0036934377 | B10: 0.0087389356 | C10: -0.0078920099 | D10: -0.0060957811 | E10: 0.0043745099 | F10: 0.093715606 | G10: -0.02807774 | H10: -0.0026926978 | I10: 0.01233587 | J10: -0.0100215 | K10: 0.00035705809 | M10: Observations | N10: 1511 | W10: Observations | X10: 1511
A11: -0.005064686 | B11: 0.0081300814 | C11: 0.0011364349 | D11: -0.005549111 | E11: 0.0054544525 | F11: 0.0025201109 | G11: 0.0083333096 | H11: 0.00016878168 | I11: 0.002751582 | J11: 0.0054229926 | K11: -0.00071480277
A12: -0.0061642271 | B12: -0.027895294 | C12: -0.019107078 | D12: -0.029955982 | E12: -0.069653028 | F12: 0.037707393 | G12: -0.004407752 | H12: -0.022102278 | I12: -0.024304226 | J12: -0.056454531 | K12: -0.025234228 | M12: ANOVA | W12: ANOVA
A13: -0.017286892 | B13: -0.0085678908 | C13: -0.00019282743 | D13: 0.008477228 | E13: 0.014294737 | F13: 0.061531059 | G13: 0.011068136 | H13: 0.0081090727 | I13: 0.013660098 | J13: -0.0083840863 | K13: 0.0055981241 | N13: df | O13: SS | P13: MS | Q13: F | R13: Significance F | X13: df | Y13: SS | Z13: MS | AA13: F | AB13: Significance F
A14: 0.02569426 | B14: 0.015637846 | C14: 0.015817885 | D14: 0.0027018963 | E14: 0.033055884 | F14: -0.073482474 | G14: 0.00054732825 | H14: 0.0088995382 | I14: 0.0099088536 | J14: -0.0042275757 | K14: 0.0074381597 | M14: Regression | N14: 1 | O14: 0.10153691 | P14: 0.10153691 | Q14: 493.67511 | R14: 7.4411992e-95 | W14: Regression | X14: 1 | Y14: 0.19243543 | Z14: 0.19243543 | AA14: 184.30295 | AB14: 1.0777759e-39
A15: 0.00932941 | B15: -0.0098595758 | C15: -0.01025437 | D15: -0.017664688 | E15: -0.0084927197 | F15: -0.0039408869 | G15: -0.010940927 | H15: -0.013231593 | I15: -0.014128692 | J15: 0.0057892697 | K15: -0.010696981 | M15: Residual | N15: 1509 | O15: 0.31036443 | P15: 0.00020567557 | W15: Residual | X15: 1509 | Y15: 1.5755855 | Z15: 0.0010441256
A16: 0.018801171 | B16: 0.015550389 | C16: 0.022064344 | D16: 0.023773206 | E16: 0.015308926 | F16: 0.038575719 | G16: 0.042035382 | H16: 0.020801158 | I16: 0.028662393 | J16: 0.051036093 | K16: 0.019936657 | M16: Total | N16: 1510 | O16: 0.41190134 | W16: Total | X16: 1510 | Y16: 1.768021
A17: 0.0035518192 | B17: 0.048488934 | C17: 0.0097616662 | D17: 0.016076243 | E17: 0.010828947 | F17: 0.013809571 | G17: 0.0015924202 | H17: 0.0057258245 | I17: -0.0011610143 | J17: 0.0010952901 | K17: 0.0099125497
A18: -0.0025390012 | B18: 0.029592686 | C18: 0.011898084 | D18: 0.0079109434 | E18: -0.0022241706 | F18: -0.015969938 | G18: 0.010598785 | H18: 0.01121899 | I18: 0.011236001 | J18: 0.017870151 | K18: 0.0096703351 | N18: Coefficients | O18: Standard Error | P18: t Stat | Q18: P-value | R18: Lower 95% | S18: Upper 95% | T18: Lower 95.0% | U18: Upper 95.0% | X18: Coefficients | Y18: Standard Error | Z18: t Stat | AA18: P-value | AB18: Lower 95% | AC18: Upper 95% | AD18: Lower 95.0% | AE18: Upper 95.0%
A19: 0.018512813 | B19: 0.0087096799 | C19: 0.00018368734 | D19: -0.0034884525 | E19: 0.0074851177 | F19: -0.019093173 | G19: -0.0052438983 | H19: 0.0069548349 | I19: 0.002298807 | J19: 0.017198134 | K19: 0.0011648684 | M19: Intercept | N19: 0.00044039568 | O19: 0.00036937942 | P19: 1.1922583 | Q19: 0.23334743 | R19: -0.00028415583 | S19: 0.0011649472 | T19: -0.00028415583 | U19: 0.0011649472 | W19: Intercept | X19: 0.0014789919 | Y19: 0.0008322575 | Z19: 1.7770845 | AA19: 0.075755724 | AB19: -0.00015351219 | AC19: 0.0031114961 | AD19: -0.00015351219 | AE19: 0.0031114961
A20: -0.011814679 | B20: -0.020599457 | C20: 0 | D20: -0.007001106 | E20: -0.016807753 | F20: 0.0082725065 | G20: 0.014233061 | H20: 0.0016444455 | I20: -0.0080274612 | J20: -0.011271546 | K20: -0.0037779199 | M20: DJI | N20: 0.90008643 | O20: 0.040510126 | P20: 22.218801 | Q20: 7.4411992e-95 | R20: 0.8206243 | S20: 0.97954855 | T20: 0.8206243 | U20: 0.97954855 | W20: DJI | X20: 1.239124 | Y20: 0.091274323 | Z20: 13.575822 | AA20: 1.0777759e-39 | AB20: 1.060086 | AC20: 1.418162 | AD20: 1.060086 | AE20: 1.418162
A21: -0.010921189 | B21: -0.0025189546 | C21: 0.012432719 | D21: -0.0096945164 | E21: 0.0013213467 | F21: -0.017857095 | G21: -0.0072765015 | H21: -0.0093580786 | I21: 0.0030828234 | J21: -0.013537555 | K21: -0.0029262785
A22: -0.0033319083 | B22: 0.02790413 | C22: 0.012096753 | D22: -0.00059330407 | E22: -0.00028864432 | F22: -0.020147371 | G22: -0.009947668 | H22: -0.010938012 | I22: -0.0084518224 | J22: 0.0014445088 | K22: -0.00011652922 | M22: BIDU | W22: TTM
A23: 0.017881435 | B23: 0.0391843 | C23: 0.041832703 | D23: 0.0234491 | E23: 0.01146742 | F23: 0.04914739 | G23: 0.025912196 | H23: 0.037868604 | I23: 0.020147275 | J23: 0.030292098 | K23: 0.019915979
A24: 0.00030552342 | B24: 0.0022458984 | C24: 0.00052145694 | D24: -0.0078306413 | E24: -0.0011826562 | F24: 0.049235229 | G24: 0.0030927419 | H24: 0.01259289 | I24: -0.0064565551 | J24: -0.015750745 | K24: -0.0035599258 | M24: Regression Statistics | W24: Regression Statistics
A25: 0.0040087411 | B25: 0.021346821 | C25: -0.0024321588 | D25: 0.018123451 | E25: 0.033664707 | F25: -0.031435124 | G25: -0.0077080981 | H25: 0 | I25: -0.016437283 | J25: -0.0049875606 | K25: 0.0041414288 | M25: Multiple R | N25: 0.47933272 | W25: Multiple R | X25: 0.54765351
A26: -0.0048672829 | B26: -0.011893742 | C26: 0.0048763513 | D26: 0.0043065669 | E26: 0.0035156092 | F26: -0.038099671 | G26: 0.0041429675 | H26: -0.00015948955 | I26: -0.013991414 | J26: -0.0017902447 | K26: -0.00051020606 | M26: R Square | N26: 0.22975985 | W26: R Square | X26: 0.29992437
A27: -0.0061520666 | B27: 0.011218873 | C27: -0.013344964 | D27: 0.0005717633 | E27: -0.015508779 | F27: -0.042053837 | G27: 0.04195078 | H27: -0.011800318 | I27: 0.0070949059 | J27: -0.004662777 | K27: -0.0020066454 | M27: Adjusted R Square | N27: 0.22924942 | W27: Adjusted R Square | X27: 0.29946044
A28: 0.0063823346 | B28: 0.011903375 | C28: 0.006674783 | D28: 0.0045714302 | E28: 0.01025548 | F28: 0.00051046452 | G28: 0.0095620832 | H28: 0.0077456881 | I28: 0.0023484305 | J28: 0.017297287 | K28: 0.0042418151 | M28: Standard Error | N28: 0.021895822 | W28: Standard Error | X28: 0.020784518
A29: -0.008939829 | B29: 0.0035404866 | C29: -0.0076775304 | D29: 0.0036974041 | E29: -0.0032452866 | F29: -0.029081582 | G29: 0.030408807 | H29: -0.0083266805 | I29: -0.021085573 | J29: -0.01629469 | K29: -0.005094053 | M29: Observations | N29: 1511 | W29: Observations | X29: 1511
A30: -0.035542187 | B30: -0.041424831 | C30: -0.023914206 | D30: -0.030320195 | E30: -0.023763657 | F30: -0.059379976 | G30: 0.041606177 | H30: -0.017889043 | I30: -0.0083765282 | J30: -0.052934864 | K30: -0.024935521
A31: 0.0063951835 | B31: -0.018758173 | C31: -0.0028822878 | D31: -0.006721182 | E31: 0.0005490488 | F31: -0.016759777 | G31: 0.01439849 | H31: -0.002649448 | I31: -0.014883365 | J31: -0.011406843 | K31: -0.0056730749 | M31: ANOVA | W31: ANOVA
A32: -0.01068359 | B32: 0.0021778584 | C32: -0.0059619439 | D32: -0.0091203924 | E32: -0.011503813 | F32: 0.040909091 | G32: -0.013278422 | H32: -0.005312953 | I32: -0.003674948 | J32: -0.0061538129 | K32: -0.0016278964 | N32: df | O32: SS | P32: MS | Q32: F | R32: Significance F | X32: df | Y32: SS | Z32: MS | AA32: F | AB32: Significance F
A33: -0.0058610129 | B33: 0.01835079 | C33: -0.0016358277 | D33: -0.00059383254 | E33: -0.001562677 | F33: 0.025109225 | G33: 0.018097534 | H33: -0.00050074307 | I33: 0.0040983474 | J33: -0.0061919615 | K33: -0.00011070594 | M33: Regression | N33: 1 | O33: 0.21580412 | P33: 0.21580412 | Q33: 450.12925 | R33: 1.2312866e-87 | W33: Regression | X33: 1 | Y33: 0.27927749 | Z33: 0.27927749 | AA33: 646.4814 | AB33: 5.4352812e-119
A34: 0.017485068 | B34: 0.0009484529 | C34: 0.01711273 | D34: 0.0029708297 | E34: 0.010152595 | F34: 0.019701756 | G34: 0.036007238 | H34: 0.015698052 | I34: 0.013951557 | J34: -0.013239877 | K34: 0.010079571 | M34: Residual | N34: 1509 | O34: 0.72345537 | P34: 0.00047942702 | W34: Residual | X34: 1509 | Y34: 0.65188223 | Z34: 0.00043199617
A35: 0.0043656099 | B35: -0.017884662 | C35: -0.008054553 | D35: 0.0044431904 | E35: -0.017063523 | F35: -0.019843342 | G35: -0.010558719 | H35: -0.011016097 | I35: 0.0044516652 | J35: 0.0015784892 | K35: 0.00093124832 | M35: Total | N35: 1510 | O35: 0.9392595 | W35: Total | X35: 1510 | Y35: 0.93115972
A36: -0.012605233 | B36: -0.020863435 | C36: -0.012811152 | D36: -0.021232715 | E36: -0.02940993 | F36: 0.0010655834 | G36: -0.021787451 | H36: -0.014297587 | I36: -0.015310233 | J36: -0.037431015 | K36: -0.013857186
A37: -0.00096047669 | B37: 0.012070402 | C37: -0.014988111 | D37: -0.0042181315 | E37: -0.012714456 | F37: 0.016498083 | G37: 0.030909112 | H37: -0.0067465368 | I37: -0.0085924825 | J37: 0.0069586818 | K37: -0.0056069188 | N37: Coefficients | O37: Standard Error | P37: t Stat | Q37: P-value | R37: Lower 95% | S37: Upper 95% | T37: Lower 95.0% | U37: Upper 95.0% | X37: Coefficients | Y37: Standard Error | Z37: t Stat | AA37: P-value | AB37: Lower 95% | AC37: Upper 95% | AD37: Lower 95.0% | AE37: Upper 95.0%
A38: -0.015382188 | B38: -0.034075637 | C38: -0.0033402886 | D38: -0.0036308142 | E38: 0.0044370036 | F38: 0.053926649 | G38: -0.016313976 | H38: 0.010358315 | I38: 0.0020635741 | J38: -0.015040689 | K38: -0.0038389875 | M38: Intercept | N38: 0.00031565585 | O38: 0.00056395259 | P38: 0.55972053 | Q38: 0.57575314 | R38: -0.0007905582 | S38: 0.0014218699 | T38: -0.0007905582 | U38: 0.0014218699 | W38: Intercept | X38: 0.00015327263 | Y38: 0.00053532965 | Z38: 0.28631449 | AA38: 0.77467656 | AB38: -0.00089679644 | AC38: 0.0012033417 | AD38: -0.00089679644 | AE38: 0.0012033417
A39: -0.023881162 | B39: -0.025576501 | C39: -0.0052131535 | D39: -0.02399032 | E39: -0.027323421 | F39: -0.046199605 | G39: -0.009412795 | H39: -0.0094117843 | I39: -0.0098846709 | J39: -0.024350012 | K39: -0.013166361 | M39: DJI | N39: 1.3122063 | O39: 0.061849116 | P39: 21.21625 | Q39: 1.2312866e-87 | R39: 1.1908869 | S39: 1.4335256 | T39: 1.1908869 | U39: 1.4335256 | W39: DJI | X39: 1.4927608 | Y39: 0.058710016 | Z39: 25.425998 | AA39: 5.4352812e-119 | AB39: 1.3775989 | AC39: 1.6079227 | AD39: 1.3775989 | AE39: 1.6079227
A40: 0.012336879 | B40: 0.012412814 | C40: 0.00056147144 | D40: -0.0009333615 | E40: 0.0071556462 | F40: 0.036458279 | G40: -0.036199156 | H40: -0.00050898401 | I40: 0.0024958504 | J40: -0.0016920017 | K40: 0.0019530369
...

Sheet AAPL
A1: Date | B1: Open | C1: High | D1: Low | E1: Close | F1: Volume | G1: Adj Close | I1: Return Close | J1: Return Adj. Close | K1: Squared Deviation
A3: 6/30/10 | B3: 256.709988 | C3: 257.96999 | D3: 250.009995 | E3: 251.530003 | F3: 184863000 | G3: 33.075655
A4: 7/1/10 | B4: 254.299999 | C4: 254.800011 | D4: 243.220013 | E4: 248.48 | F4: 255724000 | G4: 32.674586 | I4: =(E4-E3)/E3 -> -0.012125802 | J4: =(G4-G3)/G3 -> -0.012125807 | K4: =(J4-$O$8)^2 -> 0.00016809384
A5: 7/2/10 | B5: 250.490005 | C5: 250.929989 | D5: 243.200012 | E5: 246.939991 | F5: 173460700 | G5: 32.472078 | I5: =(E5-E4)/E4 -> -0.0061977181 | J5: =(G5-G4)/G4 -> -0.006197722 | K5: =(J5-$O$8)^2 -> 4.9519593e-05
A6: 7/6/10 | B6: 251.000004 | C6: 252.799992 | D6: 246.16 | E6: 248.62999 | F6: 153808900 | G6: 32.694309 | I6: =(E6-E5)/E5 -> 0.0068437639 | J6: =(G6-G5)/G5 -> 0.0068437567 | K6: =(J6-$O$8)^2 -> 3.6053573e-05 | N6: Column1
A7: 7/7/10 | B7: 250.490005 | C7: 258.770008 | D7: 249.749989 | E7: 258.670006 | F7: 163639000 | G7: 34.01455 | I7: =(E7-E6)/E6 -> 0.040381355 | J7: =(G7-G6)/G6 -> 0.04038137 | K7: =(J7-$O$8)^2 -> 0.0015635758
A8: 7/8/10 | B8: 262.48 | C8: 262.900009 | D8: 254.889999 | E8: 258.089993 | F8: 184536100 | G8: 33.938279 | I8: =(E8-E7)/E7 -> -0.0022422894 | J8: =(G8-G7)/G7 -> -0.0022423051 | K8: =(J8-$O$8)^2 -> 9.4962528e-06 | N8: Mean | O8: 0.00083929393
A9: 7/9/10 | B9: 256.889992 | C9: 259.899994 | D9: 255.159992 | E9: 259.619987 | F9: 108330600 | G9: 34.139471 | I9: =(E9-E8)/E8 -> 0.0059281415 | J9: =(G9-G8)/G8 -> 0.0059281733 | K9: =(J9-$O$8)^2 -> 2.5896693e-05 | N9: Standard Error | O9: 0.0004248894 | Q9: Sharpe Ratio
A10: 7/12/10 | B10: 258.530003 | C10: 261.849998 | D10: 254.860012 | E10: 257.290001 | F10: 140719600 | G10: 33.833082 | I10: =(E10-E9)/E9 -> -0.0089746018 | J10: =(G10-G9)/G9 -> -0.0089746265 | K10: =(J10-$O$8)^2 -> 9.6313034e-05 | N10: Median | O10: 0.00063533441 | Q10: =(O8-0)/O12 -> 0.050816641
A11: 7/13/10 | B11: 256.319992 | C11: 256.399994 | D11: 246.429993 | E11: 251.799995 | F11: 297731000 | G11: 33.111158 | I11: =(E11-E10)/E10 -> -0.021337813 | J11: =(G11-G10)/G10 -> -0.021337814 | K11: =(J11-$O$8)^2 -> 0.0004918241 | N11: Mode | O11: #N/A
A12: 7/14/10 | B12: 249.379993 | C12: 255.800007 | D12: 249.000011 | E12: 252.730003 | F12: 203011900 | G12: 33.233452 | I12: =(E12-E11)/E11 -> 0.0036934393 | J12: =(G12-G11)/G11 -> 0.0036934377 | K12: =(J12-$O$8)^2 -> 8.1461368e-06 | N12: Standard Deviation | O12: 0.016516124
A13: 7/15/10 | B13: 248.230007 | C13: 256.969994 | D13: 247.299999 | E13: 251.450001 | F13: 206216500 | G13: 33.065135 | I13: =(E13-E12)/E12 -> -0.0050647014 | J13: =(G13-G12)/G12 -> -0.005064686 | K13: =(J13-$O$8)^2 -> 3.4856979e-05 | N13: Sample Variance | O13: 0.00027278234
A14: 7/16/10 | B14: 253.18 | C14: 254.970001 | D14: 248.410011 | E14: 249.900005 | F14: 259964600 | G14: 32.861314 | I14: =(E14-E13)/E13 -> -0.0061642314 | J14: =(G14-G13)/G13 -> -0.0061642271 | K14: =(J14-$O$8)^2 -> 4.9049306e-05 | N14: Kurtosis | O14: 4.4418
A15: 7/19/10 | B15: 249.880005 | C15: 249.880005 | D15: 239.60001 | E15: 245.580013 | F15: 256119500 | G15: 32.293244 | I15: =(E15-E14)/E14 -> -0.017286882 | J15: =(G15-G14)/G14 -> -0.017286892 | K15: =(J15-$O$8)^2 -> 0.00032855863 | N15: Skewness | O15: -0.1978243
A16: 7/20/10 | B16: 242.900005 | C16: 252.899994 | D16: 240.010006 | E16: 251.890011 | F16: 268737700 | G16: 33.122995 | I16: =(E16-E15)/E15 -> 0.025694265 | J16: =(G16-G15)/G15 -> 0.02569426 | K16: =(J16-$O$8)^2 -> 0.00061776933 | N16: Range | O16: 0.21229933
A17: 7/21/10 | B17: 265.089993 | C17: 265.149994 | D17: 253.999992 | E17: 254.239998 | F17: 296417800 | G17: 33.432013 | I17: =(E17-E16)/E16 -> 0.0093294172 | J17: =(G17-G16)/G16 -> 0.00932941 | K17: =(J17-$O$8)^2 -> 7.208207e-05 | N17: Minimum | O17: -0.12355796
A18: 7/22/10 | B18: 257.679996 | C18: 259.999996 | D18: 255.310009 | E18: 259.02 | F18: 161329700 | G18: 34.060574 | I18: =(E18-E17)/E17 -> 0.018801141 | J18: =(G18-G17)/G17 -> 0.018801171 | K18: =(J18-$O$8)^2 -> 0.00032262903 | N18: Maximum | O18: 0.088741367
A19: 7/23/10 | B19: 257.089996 | C19: 260.380005 | D19: 256.279991 | E19: 259.939995 | F19: 133347200 | G19: 34.181551 | I19: =(E19-E18)/E18 -> 0.00355183 | J19: =(G19-G18)/G18 -> 0.0035518192 | K19: =(J19-$O$8)^2 -> 7.3577932e-06 | N19: Sum | O19: 1.2681731
A20: 7/26/10 | B20: 259.999996 | C20: 260.099998 | D20: 257.710011 | E20: 259.280006 | F20: 105137900 | G20: 34.094764 | I20: =(E20-E19)/E19 -> -0.0025390052 | J20: =(G20-G19)/G19 -> -0.0025390012 | K20: =(J20-$O$8)^2 -> 1.1412878e-05 | N20: Count | O20: 1511
A21: 7/27/10 | B21: 260.870003 | C21: 264.799999 | D21: 260.300003 | E21: 264.080009 | F21: 146192900 | G21: 34.725954 | I21: =(E21-E20)/E20 -> 0.018512816 | J21: =(G21-G20)/G20 -> 0.018512813 | K21: =(J21-$O$8)^2 -> 0.00031235329 | N21: Confidence Level(095%) | O21: 0.00083343596
A22: 7/28/10 | B22: 263.669987 | C22: 265.990013 | D22: 260.249989 | E22: 260.959991 | F22: 129996300 | G22: 34.315678 | I22: =(E22-E21)/E21 -> -0.011814669 | J22: =(G22-G21)/G21 -> -0.011814679 | K22: =(J22-$O$8)^2 -> 0.00016012303
A23: 7/29/10 | B23: 260.709999 | C23: 262.64999 | D23: 256.099987 | E23: 258.109993 | F23: 160951700 | G23: 33.94091 | I23: =(E23-E22)/E22 -> -0.010921207 | J23: =(G23-G22)/G22 -> -0.010921189 | K23: =(J23-$O$8)^2 -> 0.00013830896
A24: 7/30/10 | B24: 255.889996 | C24: 259.699989 | D24: 254.900013 | E24: 257.25 | F24: 112052500 | G24: 33.827822 | I24: =(E24-E23)/E23 -> -0.0033318857 | J24: =(G24-G23)/G23 -> -0.0033319083 | K24: =(J24-$O$8)^2 -> 1.7398928e-05
A25: 8/2/10 | B25: 260.440006 | C25: 262.589989 | D25: 259.619987 | E25: 261.849998 | F25: 107013900 | G25: 34.432712 | I25: =(E25-E24)/E24 -> 0.017881431 | J25: =(G25-G24)/G24 -> 0.017881435 | K25: =(J25-$O$8)^2 -> 0.00029043457
A26: 8/3/10 | B26: 261.010006 | C26: 263.259991 | D26: 259.42001 | E26: 261.93 | F26: 104413400 | G26: 34.443232 | I26: =(E26-E25)/E25 -> 0.00030552607 | J26: =(G26-G25)/G25 -> 0.00030552342 | K26: =(J26-$O$8)^2 -> 2.8491096e-07
A27: 8/4/10 | B27: 262.840008 | C27: 264.279987 | D27: 260.30999 | E27: 262.980011 | F27: 105093800 | G27: 34.581306 | I27: =(E27-E26)/E26 -> 0.0040087466 | J27: =(G27-G26)/G26 -> 0.0040087411 | K27: =(J27-$O$8)^2 -> 1.0045395e-05
A28: 8/5/10 | B28: 261.729996 | C28: 263.179989 | D28: 260.549995 | E28: 261.700008 | F28: 72274300 | G28: 34.412989 | I28: =(E28-E27)/E27 -> -0.0048673015 | J28: =(G28-G27)/G27 -> -0.0048672829 | K28: =(J28-$O$8)^2 -> 3.2565019e-05
A29: 8/6/10 | B29: 259.779991 | C29: 261.48999 | D29: 257.630009 | E29: 260.090012 | F29: 111224400 | G29: 34.201278 | I29: =(E29-E28)/E28 -> -0.0061520671 | J29: =(G29-G28)/G28 -> -0.0061520666 | K29: =(J29-$O$8)^2 -> 4.8879122e-05
A30: 8/9/10 | B30: 261.480003 | C30: 262.150005 | D30: 259.57 | E30: 261.749996 | F30: 75782000 | G30: 34.419562 | I30: =(E30-E29)/E29 -> 0.0063823443 | J30: =(G30-G29)/G29 -> 0.0063823346 | K30: =(J30-$O$8)^2 -> 3.07253e-05
A31: 8/10/10 | B31: 259.850006 | C31: 260.449993 | D31: 257.550007 | E31: 259.409996 | F31: 112980000 | G31: 34.111857 | I31: =(E31-E30)/E30 -> -0.0089398282 | J31: =(G31-G30)/G30 -> -0.008939829 | K31: =(J31-$O$8)^2 -> 9.5631246e-05
A32: 8/11/10 | B32: 255.399998 | C32: 255.689991 | D32: 249.80999 | E32: 250.189999 | F32: 155013600 | G32: 32.899447 | I32: =(E32-E31)/E31 -> -0.035542181 | J32: =(G32-G31)/G31 -> -0.035542187 | K32: =(J32-$O$8)^2 -> 0.0013236122
A33: 8/12/10 | B33: 246.689999 | C33: 253.099998 | D33: 246.119999 | E33: 251.790009 | F33: 133730100 | G33: 33.109845 | I33: =(E33-E32)/E32 -> 0.0063951797 | J33: =(G33-G32)/G32 -> 0.0063951835 | K33: =(J33-$O$8)^2 -> 3.0867909e-05
... A1514: 6/30/16 | B1514: 94.440002 | C1514: 95.769997 | D1514: 94.300003 | E1514: 95.599998 | F1514: 35836400 | G1514: 95.599998 | I1514: =(E1514-E1513)/E1513 -> 0.012711822 | J1514: =(G1514-G1513)/G1513 -> 0.012711822 | K1514: =(J1514-$O$8)^2 -> 0.00014095692

Sheet BIDU
A1: Date | B1: Open | C1: High | D1: Low | E1: Close | F1: Volume | G1: Adj Close | I1: Return Close | J1: Return Adj. Close | K1: Squared Deviation
A3: 6/30/10 | B3: 67.980003 | C3: 70.349998 | D3: 67.68 | E3: 68.080002 | F3: 15191200 | G3: 68.080002
A4: 7/1/10 | B4: 69.349998 | C4: 69.879997 | D4: 65.900002 | E4: 68.550003 | F4: 11540100 | G4: 68.550003 | I4: =(E4-E3)/E3 -> 0.0069036573 | J4: =(G4-G3)/G3 -> 0.0069036573 | K4: =(J4-$O$8)^2 -> 3.6077572e-05
A5: 7/2/10 | B5: 69.379997 | C5: 69.410004 | D5: 67.160004 | E5: 67.550003 | F5: 6293500 | G5: 67.550003 | I5: =(E5-E4)/E4 -> -0.014587891 | J5: =(G5-G4)/G4 -> -0.014587891 | K5: =(J5-$O$8)^2 -> 0.00023978795
A6: 7/6/10 | B6: 69.199997 | C6: 70.059998 | D6: 66.849998 | E6: 67.449997 | F6: 9658200 | G6: 67.449997 | I6: =(E6-E5)/E5 -> -0.0014804737 | J6: =(G6-G5)/G5 -> -0.0014804737 | K6: =(J6-$O$8)^2 -> 5.6533151e-06 | N6: Column1
A7: 7/7/10 | B7: 67.519997 | C7: 72.440002 | D7: 67.25 | E7: 72.370003 | F7: 12808300 | G7: 72.370003 | I7: =(E7-E6)/E6 -> 0.072943013 | J7: =(G7-G6)/G6 -> 0.072943013 | K7: =(J7-$O$8)^2 -> 0.0051905997
A8: 7/8/10 | B8: 73.300003 | C8: 73.75 | D8: 71.099998 | E8: 72.43 | F8: 11403400 | G8: 72.43 | I8: =(E8-E7)/E7 -> 0.00082903133 | J8: =(G8-G7)/G7 -> 0.00082903133 | K8: =(J8-$O$8)^2 -> 4.6464823e-09 | N8: Mean | O8: 0.00089719644
A9: 7/9/10 | B9: 70.199997 | C9: 71.839996 | D9: 70.080002 | E9: 71.199997 | F9: 14945000 | G9: 71.199997 | I9: =(E9-E8)/E8 -> -0.016981955 | J9: =(G9-G8)/G8 -> -0.016981955 | K9: =(J9-$O$8)^2 -> 0.00031966406 | N9: Standard Error | O9: 0.00064161143 | Q9: Sharpe Ratio
A10: 7/12/10 | B10: 70.68 | C10: 71.779999 | D10: 70.349998 | E10: 70.730003 | F10: 8280100 | G10: 70.730003 | I10: =(E10-E9)/E9 -> -0.0066010396 | J10: =(G10-G9)/G9 -> -0.0066010396 | K10: =(J10-$O$8)^2 -> 5.6223544e-05 | N10: Median | O10: -0.00034749217 | Q10: =(O8-0)/O12 -> 0.035973543
A11: 7/13/10 | B11: 72.160004 | C11: 74.800003 | D11: 71.389999 | E11: 74.379997 | F11: 13455900 | G11: 74.379997 | I11: =(E11-E10)/E10 -> 0.051604607 | J11: =(G11-G10)/G10 -> 0.051604607 | K11: =(J11-$O$8)^2 -> 0.0025712415 | N11: Mode | O11: 0
A12: 7/14/10 | B12: 75.139999 | C12: 75.480003 | D12: 73.989998 | E12: 75.029999 | F12: 9501900 | G12: 75.029999 | I12: =(E12-E11)/E11 -> 0.0087389356 | J12: =(G12-G11)/G11 -> 0.0087389356 | K12: =(J12-$O$8)^2 -> 6.1492872e-05 | N12: Standard Deviation | O12: 0.024940452
A13: 7/15/10 | B13: 75.010002 | C13: 75.860001 | D13: 74.110001 | E13: 75.639999 | F13: 8528600 | G13: 75.639999 | I13: =(E13-E12)/E12 -> 0.0081300814 | J13: =(G13-G12)/G12 -> 0.0081300814 | K13: =(J13-$O$8)^2 -> 5.2314625e-05 | N13: Sample Variance | O13: 0.00062202616
A14: 7/16/10 | B14: 75.230003 | C14: 75.699997 | D14: 73.290001 | E14: 73.529999 | F14: 10384900 | G14: 73.529999 | I14: =(E14-E13)/E13 -> -0.027895294 | J14: =(G14-G13)/G13 -> -0.027895294 | K14: =(J14-$O$8)^2 -> 0.0008290075 | N14: Kurtosis | O14: 2.5986624
A15: 7/19/10 | B15: 71.669998 | C15: 73.389999 | D15: 70.379997 | E15: 72.900002 | F15: 15400600 | G15: 72.900002 | I15: =(E15-E14)/E14 -> -0.0085678908 | J15: =(G15-G14)/G14 -> -0.0085678908 | K15: =(J15-$O$8)^2 -> 8.9587876e-05 | N15: Skewness | O15: 0.093423081
A16: 7/20/10 | B16: 71.260002 | C16: 74.230003 | D16: 70.75 | E16: 74.040001 | F16: 9721000 | G16: 74.040001 | I16: =(E16-E15)/E15 -> 0.015637846 | J16: =(G16-G15)/G15 -> 0.015637846 | K16: =(J16-$O$8)^2 -> 0.00021728675 | N16: Range | O16: 0.26007184
A17: 7/21/10 | B17: 74.980003 | C17: 76.580002 | D17: 73 | E17: 73.309998 | F17: 18796800 | G17: 73.309998 | I17: =(E17-E16)/E16 -> -0.0098595758 | J17: =(G17-G16)/G16 -> -0.0098595758 | K17: =(J17-$O$8)^2 -> 0.00011570815 | N17: Minimum | O17: -0.14998986
A18: 7/22/10 | B18: 76.379997 | C18: 76.459999 | D18: 72.300003 | E18: 74.449997 | F18: 19747500 | G18: 74.449997 | I18: =(E18-E17)/E17 -> 0.015550389 | J18: =(G18-G17)/G17 -> 0.015550389 | K18: =(J18-$O$8)^2 -> 0.00021471606 | N18: Maximum | O18: 0.11008199
A19: 7/23/10 | B19: 75.400002 | C19: 78.220001 | D19: 74.5 | E19: 78.059998 | F19: 13308300 | G19: 78.059998 | I19: =(E19-E18)/E18 -> 0.048488934 | J19: =(G19-G18)/G18 -> 0.048488934 | K19: =(J19-$O$8)^2 -> 0.0022649735 | N19: Sum | O19: 1.3556638
A20: 7/26/10 | B20: 78.870003 | C20: 80.870003 | D20: 78.300003 | E20: 80.370003 | F20: 13939300 | G20: 80.370003 | I20: =(E20-E19)/E19 -> 0.029592686 | J20: =(G20-G19)/G19 -> 0.029592686 | K20: =(J20-$O$8)^2 -> 0.00082343111 | N20: Count | O20: 1511
A21: 7/27/10 | B21: 80.730003 | C21: 81.989998 | D21: 80.110001 | E21: 81.07 | F21: 10737400 | G21: 81.07 | I21: =(E21-E20)/E20 -> 0.0087096799 | J21: =(G21-G20)/G20 -> 0.0087096799 | K21: =(J21-$O$8)^2 -> 6.1034898e-05 | N21: Confidence Level(095%) | O21: 0.0012585441
A22: 7/28/10 | B22: 80.779999 | C22: 81.18 | D22: 78.879997 | E22: 79.400002 | F22: 7746700 | G22: 79.400002 | I22: =(E22-E21)/E21 -> -0.020599457 | J22: =(G22-G21)/G21 -> -0.020599457 | K22: =(J22-$O$8)^2 -> 0.00046210612
A23: 7/29/10 | B23: 80.089996 | C23: 80.459999 | D23: 77.639999 | E23: 79.199997 | F23: 9387900 | G23: 79.199997 | I23: =(E23-E22)/E22 -> -0.0025189546 | J23: =(G23-G22)/G22 -> -0.0025189546 | K23: =(J23-$O$8)^2 -> 1.1670088e-05
A24: 7/30/10 | B24: 79.400002 | C24: 81.550003 | D24: 78.300003 | E24: 81.410004 | F24: 12327800 | G24: 81.410004 | I24: =(E24-E23)/E23 -> 0.02790413 | J24: =(G24-G23)/G23 -> 0.02790413 | K24: =(J24-$O$8)^2 -> 0.00072937445
A25: 8/2/10 | B25: 83.029999 | C25: 84.980003 | D25: 82.900002 | E25: 84.599998 | F25: 13600000 | G25: 84.599998 | I25: =(E25-E24)/E24 -> 0.0391843 | J25: =(G25-G24)/G24 -> 0.0391843 | K25: =(J25-$O$8)^2 -> 0.0014659023
A26: 8/3/10 | B26: 84.620003 | C26: 85.349998 | D26: 82.800003 | E26: 84.790001 | F26: 10146900 | G26: 84.790001 | I26: =(E26-E25)/E25 -> 0.0022458984 | J26: =(G26-G25)/G25 -> 0.0022458984 | K26: =(J26-$O$8)^2 -> 1.818997e-06
A27: 8/4/10 | B27: 85.410004 | C27: 86.910004 | D27: 85.07 | E27: 86.599998 | F27: 11704500 | G27: 86.599998 | I27: =(E27-E26)/E26 -> 0.021346821 | J27: =(G27-G26)/G26 -> 0.021346821 | K27: =(J27-$O$8)^2 -> 0.00041818716
A28: 8/5/10 | B28: 86.260002 | C28: 86.459999 | D28: 84.849998 | E28: 85.57 | F28: 8026600 | G28: 85.57 | I28: =(E28-E27)/E27 -> -0.011893742 | J28: =(G28-G27)/G27 -> -0.011893742 | K28: =(J28-$O$8)^2 -> 0.0001636081
A29: 8/6/10 | B29: 84.639999 | C29: 86.599998 | D29: 84.330002 | E29: 86.529999 | F29: 8692300 | G29: 86.529999 | I29: =(E29-E28)/E28 -> 0.011218873 | J29: =(G29-G28)/G28 -> 0.011218873 | K29: =(J29-$O$8)^2 -> 0.00010653702
A30: 8/9/10 | B30: 87.449997 | C30: 88 | D30: 86.699997 | E30: 87.559998 | F30: 8792800 | G30: 87.559998 | I30: =(E30-E29)/E29 -> 0.011903375 | J30: =(G30-G29)/G29 -> 0.011903375 | K30: =(J30-$O$8)^2 -> 0.00012113596
